{
  "GSD": {
    "alias": "CVE-2023-6597",
    "id": "GSD-2023-6597"
  },
  "gsd": {
    "metadata": {
      "exploitCode": "unknown",
      "remediation": "unknown",
      "reportConfidence": "confirmed",
      "type": "vulnerability"
    },
    "osvSchema": {
      "aliases": [
        "CVE-2023-6597"
      ],
      "details": "An issue was found in the CPython `tempfile.TemporaryDirectory` class affecting versions 3.12.2, 3.11.8, 3.10.13, 3.9.18, and 3.8.18 and prior.\n\nThe tempfile.TemporaryDirectory class would dereference symlinks during cleanup of permissions-related errors. This means users which can run privileged programs are potentially able to modify permissions of files referenced by symlinks in some circumstances.\n",
      "id": "GSD-2023-6597",
      "modified": "2023-12-13T01:20:32.861759Z",
      "schema_version": "1.4.0"
    }
  },
  "namespaces": {
    "cve.org": {
      "CVE_data_meta": {
        "ASSIGNER": "cna@python.org",
        "ID": "CVE-2023-6597",
        "STATE": "PUBLIC"
      },
      "affects": {
        "vendor": {
          "vendor_data": [
            {
              "product": {
                "product_data": [
                  {
                    "product_name": "CPython",
                    "version": {
                      "version_data": [
                        {
                          "version_affected": "<=",
                          "version_name": "3.12.0",
                          "version_value": "3.12.2"
                        },
                        {
                          "version_affected": "<=",
                          "version_name": "3.11.0",
                          "version_value": "3.11.8"
                        },
                        {
                          "version_affected": "<=",
                          "version_name": "3.10.0",
                          "version_value": "3.10.13"
                        },
                        {
                          "version_affected": "<=",
                          "version_name": "3.9.0",
                          "version_value": "3.9.18"
                        },
                        {
                          "version_affected": "<=",
                          "version_name": "0",
                          "version_value": "3.8.18"
                        }
                      ]
                    }
                  }
                ]
              },
              "vendor_name": "Python Software Foundation"
            }
          ]
        }
      },
      "data_format": "MITRE",
      "data_type": "CVE",
      "data_version": "4.0",
      "description": {
        "description_data": [
          {
            "lang": "eng",
            "value": "An issue was found in the CPython `tempfile.TemporaryDirectory` class affecting versions 3.12.2, 3.11.8, 3.10.13, 3.9.18, and 3.8.18 and prior.\n\nThe tempfile.TemporaryDirectory class would dereference symlinks during cleanup of permissions-related errors. This means users which can run privileged programs are potentially able to modify permissions of files referenced by symlinks in some circumstances.\n"
          }
        ]
      },
      "generator": {
        "engine": "Vulnogram 0.1.0-dev"
      },
      "impact": {
        "cvss": [
          {
            "attackComplexity": "HIGH",
            "attackVector": "LOCAL",
            "availabilityImpact": "NONE",
            "baseScore": 7.8,
            "baseSeverity": "HIGH",
            "confidentialityImpact": "HIGH",
            "integrityImpact": "HIGH",
            "privilegesRequired": "NONE",
            "scope": "CHANGED",
            "userInteraction": "NONE",
            "vectorString": "CVSS:3.1/AV:L/AC:H/PR:N/UI:N/S:C/C:H/I:H/A:N",
            "version": "3.1"
          }
        ]
      },
      "problemtype": {
        "problemtype_data": [
          {
            "description": [
              {
                "lang": "eng",
                "value": "n/a"
              }
            ]
          }
        ]
      },
      "references": {
        "reference_data": [
          {
            "name": "https://github.com/python/cpython/commit/81c16cd94ec38d61aa478b9a452436dc3b1b524d",
            "refsource": "MISC",
            "url": "https://github.com/python/cpython/commit/81c16cd94ec38d61aa478b9a452436dc3b1b524d"
          },
          {
            "name": "https://github.com/python/cpython/commit/6ceb8aeda504b079fef7a57b8d81472f15cdd9a5",
            "refsource": "MISC",
            "url": "https://github.com/python/cpython/commit/6ceb8aeda504b079fef7a57b8d81472f15cdd9a5"
          },
          {
            "name": "https://github.com/python/cpython/commit/5585334d772b253a01a6730e8202ffb1607c3d25",
            "refsource": "MISC",
            "url": "https://github.com/python/cpython/commit/5585334d772b253a01a6730e8202ffb1607c3d25"
          },
          {
            "name": "https://github.com/python/cpython/commit/8eaeefe49d179ca4908d052745e3bb8b6f238f82",
            "refsource": "MISC",
            "url": "https://github.com/python/cpython/commit/8eaeefe49d179ca4908d052745e3bb8b6f238f82"
          },
          {
            "name": "https://github.com/python/cpython/commit/d54e22a669ae6e987199bb5d2c69bb5a46b0083b",
            "refsource": "MISC",
            "url": "https://github.com/python/cpython/commit/d54e22a669ae6e987199bb5d2c69bb5a46b0083b"
          },
          {
            "name": "https://github.com/python/cpython/commit/02a9259c717738dfe6b463c44d7e17f2b6d2cb3a",
            "refsource": "MISC",
            "url": "https://github.com/python/cpython/commit/02a9259c717738dfe6b463c44d7e17f2b6d2cb3a"
          },
          {
            "name": "https://github.com/python/cpython/issues/91133",
            "refsource": "MISC",
            "url": "https://github.com/python/cpython/issues/91133"
          },
          {
            "name": "https://mail.python.org/archives/list/security-announce@python.org/thread/Q5C6ATFC67K53XFV4KE45325S7NS62LD/",
            "refsource": "MISC",
            "url": "https://mail.python.org/archives/list/security-announce@python.org/thread/Q5C6ATFC67K53XFV4KE45325S7NS62LD/"
          }
        ]
      },
      "source": {
        "discovery": "UNKNOWN"
      }
    },
    "nvd.nist.gov": {
      "cve": {
        "descriptions": [
          {
            "lang": "en",
            "value": "An issue was found in the CPython `tempfile.TemporaryDirectory` class affecting versions 3.12.2, 3.11.8, 3.10.13, 3.9.18, and 3.8.18 and prior.\n\nThe tempfile.TemporaryDirectory class would dereference symlinks during cleanup of permissions-related errors. This means users which can run privileged programs are potentially able to modify permissions of files referenced by symlinks in some circumstances.\n"
          },
          {
            "lang": "es",
            "value": "Se encontr\u00f3 un problema en la clase CPython `tempfile.TemporaryDirectory` que afecta a las versiones 3.12.2, 3.11.8, 3.10.13, 3.9.18 y 3.8.18 y anteriores. La clase tempfile.TemporaryDirectory eliminar\u00eda la referencia a enlaces simb\u00f3licos durante la limpieza de errores relacionados con permisos. Esto significa que los usuarios que pueden ejecutar programas privilegiados pueden modificar los permisos de los archivos a los que hacen referencia los enlaces simb\u00f3licos en algunas circunstancias."
          }
        ],
        "id": "CVE-2023-6597",
        "lastModified": "2024-03-24T23:15:08.920",
        "metrics": {
          "cvssMetricV31": [
            {
              "cvssData": {
                "attackComplexity": "HIGH",
                "attackVector": "LOCAL",
                "availabilityImpact": "NONE",
                "baseScore": 7.8,
                "baseSeverity": "HIGH",
                "confidentialityImpact": "HIGH",
                "integrityImpact": "HIGH",
                "privilegesRequired": "NONE",
                "scope": "CHANGED",
                "userInteraction": "NONE",
                "vectorString": "CVSS:3.1/AV:L/AC:H/PR:N/UI:N/S:C/C:H/I:H/A:N",
                "version": "3.1"
              },
              "exploitabilityScore": 1.4,
              "impactScore": 5.8,
              "source": "cna@python.org",
              "type": "Secondary"
            }
          ]
        },
        "published": "2024-03-19T16:15:08.743",
        "references": [
          {
            "source": "cna@python.org",
            "url": "https://github.com/python/cpython/commit/02a9259c717738dfe6b463c44d7e17f2b6d2cb3a"
          },
          {
            "source": "cna@python.org",
            "url": "https://github.com/python/cpython/commit/5585334d772b253a01a6730e8202ffb1607c3d25"
          },
          {
            "source": "cna@python.org",
            "url": "https://github.com/python/cpython/commit/6ceb8aeda504b079fef7a57b8d81472f15cdd9a5"
          },
          {
            "source": "cna@python.org",
            "url": "https://github.com/python/cpython/commit/81c16cd94ec38d61aa478b9a452436dc3b1b524d"
          },
          {
            "source": "cna@python.org",
            "url": "https://github.com/python/cpython/commit/8eaeefe49d179ca4908d052745e3bb8b6f238f82"
          },
          {
            "source": "cna@python.org",
            "url": "https://github.com/python/cpython/commit/d54e22a669ae6e987199bb5d2c69bb5a46b0083b"
          },
          {
            "source": "cna@python.org",
            "url": "https://github.com/python/cpython/issues/91133"
          },
          {
            "source": "cna@python.org",
            "url": "https://lists.debian.org/debian-lts-announce/2024/03/msg00025.html"
          },
          {
            "source": "cna@python.org",
            "url": "https://mail.python.org/archives/list/security-announce@python.org/thread/Q5C6ATFC67K53XFV4KE45325S7NS62LD/"
          }
        ],
        "sourceIdentifier": "cna@python.org",
        "vulnStatus": "Awaiting Analysis"
      }
    }
  }
}