{
    "GSD": {
        "alias": "CVE-2020-29651",
        "description": "A denial of service via regular expression in the py.path.svnwc component of py (aka python-py) through 1.9.0 could be used by attackers to cause a compute-time denial of service attack by supplying malicious input to the blame functionality.",
        "id": "GSD-2020-29651"
    },
    "namespaces": {
        "cve.org": {
            "CVE_data_meta": {
                "ASSIGNER": "cve@mitre.org",
                "ID": "CVE-2020-29651",
                "STATE": "PUBLIC"
            },
            "affects": {
                "vendor": {
                    "vendor_data": [
                        {
                            "product": {
                                "product_data": [
                                    {
                                        "product_name": "n/a",
                                        "version": {
                                            "version_data": [
                                                {
                                                    "version_value": "n/a"
                                                }
                                            ]
                                        }
                                    }
                                ]
                            },
                            "vendor_name": "n/a"
                        }
                    ]
                }
            },
            "data_format": "MITRE",
            "data_type": "CVE",
            "data_version": "4.0",
            "description": {
                "description_data": [
                    {
                        "lang": "eng",
                        "value": "A denial of service via regular expression in the py.path.svnwc component of py (aka python-py) through 1.9.0 could be used by attackers to cause a compute-time denial of service attack by supplying malicious input to the blame functionality."
                    }
                ]
            },
            "problemtype": {
                "problemtype_data": [
                    {
                        "description": [
                            {
                                "lang": "eng",
                                "value": "n/a"
                            }
                        ]
                    }
                ]
            },
            "references": {
                "reference_data": [
                    {
                        "name": "https://github.com/pytest-dev/py/issues/256",
                        "refsource": "MISC",
                        "url": "https://github.com/pytest-dev/py/issues/256"
                    },
                    {
                        "name": "https://github.com/pytest-dev/py/pull/257",
                        "refsource": "MISC",
                        "url": "https://github.com/pytest-dev/py/pull/257"
                    },
                    {
                        "name": "https://github.com/pytest-dev/py/pull/257/commits/4a9017dc6199d2a564b6e4b0aa39d6d8870e4144",
                        "refsource": "MISC",
                        "url": "https://github.com/pytest-dev/py/pull/257/commits/4a9017dc6199d2a564b6e4b0aa39d6d8870e4144"
                    },
                    {
                        "name": "FEDORA-2020-db0eb54982",
                        "refsource": "FEDORA",
                        "url": "https://lists.fedoraproject.org/archives/list/package-announce@lists.fedoraproject.org/message/AYWNYEV3FGDHPIHX4DDUDMFZ6NLCQRC4/"
                    },
                    {
                        "name": "FEDORA-2020-8371993b6b",
                        "refsource": "FEDORA",
                        "url": "https://lists.fedoraproject.org/archives/list/package-announce@lists.fedoraproject.org/message/CHDTINIBJZ67T3W74QTBIY5LPKAXEOGR/"
                    }
                ]
            }
        },
        "gitlab.com": {
            "advisories": [
                {
                    "affected_range": "<=1.9.0",
                    "affected_versions": "All versions up to 1.9.0",
                    "cvss_v2": "AV:N/AC:L/Au:N/C:N/I:N/A:P",
                    "cvss_v3": "CVSS:3.1/AV:N/AC:L/PR:N/UI:N/S:U/C:N/I:N/A:H",
                    "cwe_ids": [
                        "CWE-1035",
                        "CWE-937"
                    ],
                    "date": "2021-01-05",
                    "description": "A denial of service via regular expression in the `py.path.svnwc` component of py (aka python-py) could be used by attackers to cause a compute-time denial of service attack by supplying malicious input to the blame functionality.",
                    "fixed_versions": [
                        "1.10.0"
                    ],
                    "identifier": "CVE-2020-29651",
                    "identifiers": [
                        "CVE-2020-29651"
                    ],
                    "not_impacted": "All versions after 1.9.0",
                    "package_slug": "pypi/py",
                    "pubdate": "2020-12-09",
                    "solution": "Upgrade to version 1.10.0 or above.",
                    "title": "Uncontrolled Resource Consumption",
                    "urls": [
                        "https://nvd.nist.gov/vuln/detail/CVE-2020-29651"
                    ],
                    "uuid": "b261be86-c801-45fa-8477-bc4fdbd496ea"
                }
            ]
        },
        "nvd.nist.gov": {
            "configurations": {
                "CVE_data_version": "4.0",
                "nodes": [
                    {
                        "children": [],
                        "cpe_match": [
                            {
                                "cpe23Uri": "cpe:2.3:a:pytest:py:*:*:*:*:*:*:*:*",
                                "cpe_name": [],
                                "versionEndIncluding": "1.9.0",
                                "vulnerable": true
                            }
                        ],
                        "operator": "OR"
                    }
                ]
            },
            "cve": {
                "CVE_data_meta": {
                    "ASSIGNER": "cve@mitre.org",
                    "ID": "CVE-2020-29651"
                },
                "data_format": "MITRE",
                "data_type": "CVE",
                "data_version": "4.0",
                "description": {
                    "description_data": [
                        {
                            "lang": "en",
                            "value": "A denial of service via regular expression in the py.path.svnwc component of py (aka python-py) through 1.9.0 could be used by attackers to cause a compute-time denial of service attack by supplying malicious input to the blame functionality."
                        }
                    ]
                },
                "problemtype": {
                    "problemtype_data": [
                        {
                            "description": [
                                {
                                    "lang": "en",
                                    "value": "NVD-CWE-Other"
                                }
                            ]
                        }
                    ]
                },
                "references": {
                    "reference_data": [
                        {
                            "name": "https://github.com/pytest-dev/py/pull/257/commits/4a9017dc6199d2a564b6e4b0aa39d6d8870e4144",
                            "refsource": "MISC",
                            "tags": [
                                "Patch",
                                "Third Party Advisory"
                            ],
                            "url": "https://github.com/pytest-dev/py/pull/257/commits/4a9017dc6199d2a564b6e4b0aa39d6d8870e4144"
                        },
                        {
                            "name": "https://github.com/pytest-dev/py/issues/256",
                            "refsource": "MISC",
                            "tags": [
                                "Third Party Advisory"
                            ],
                            "url": "https://github.com/pytest-dev/py/issues/256"
                        },
                        {
                            "name": "https://github.com/pytest-dev/py/pull/257",
                            "refsource": "MISC",
                            "tags": [
                                "Third Party Advisory"
                            ],
                            "url": "https://github.com/pytest-dev/py/pull/257"
                        },
                        {
                            "name": "FEDORA-2020-db0eb54982",
                            "refsource": "FEDORA",
                            "tags": [],
                            "url": "https://lists.fedoraproject.org/archives/list/package-announce@lists.fedoraproject.org/message/AYWNYEV3FGDHPIHX4DDUDMFZ6NLCQRC4/"
                        },
                        {
                            "name": "FEDORA-2020-8371993b6b",
                            "refsource": "FEDORA",
                            "tags": [],
                            "url": "https://lists.fedoraproject.org/archives/list/package-announce@lists.fedoraproject.org/message/CHDTINIBJZ67T3W74QTBIY5LPKAXEOGR/"
                        }
                    ]
                }
            },
            "impact": {
                "baseMetricV2": {
                    "acInsufInfo": false,
                    "cvssV2": {
                        "accessComplexity": "LOW",
                        "accessVector": "NETWORK",
                        "authentication": "NONE",
                        "availabilityImpact": "PARTIAL",
                        "baseScore": 5.0,
                        "confidentialityImpact": "NONE",
                        "integrityImpact": "NONE",
                        "vectorString": "AV:N/AC:L/Au:N/C:N/I:N/A:P",
                        "version": "2.0"
                    },
                    "exploitabilityScore": 10.0,
                    "impactScore": 2.9,
                    "obtainAllPrivilege": false,
                    "obtainOtherPrivilege": false,
                    "obtainUserPrivilege": false,
                    "severity": "MEDIUM",
                    "userInteractionRequired": false
                },
                "baseMetricV3": {
                    "cvssV3": {
                        "attackComplexity": "LOW",
                        "attackVector": "NETWORK",
                        "availabilityImpact": "HIGH",
                        "baseScore": 7.5,
                        "baseSeverity": "HIGH",
                        "confidentialityImpact": "NONE",
                        "integrityImpact": "NONE",
                        "privilegesRequired": "NONE",
                        "scope": "UNCHANGED",
                        "userInteraction": "NONE",
                        "vectorString": "CVSS:3.1/AV:N/AC:L/PR:N/UI:N/S:U/C:N/I:N/A:H",
                        "version": "3.1"
                    },
                    "exploitabilityScore": 3.9,
                    "impactScore": 3.6
                }
            },
            "lastModifiedDate": "2021-01-05T03:15Z",
            "publishedDate": "2020-12-09T07:15Z"
        }
    }
}